Workbook

Sheet Indexable Inserts
A1: Item Number | B1: Insert box size LxHxW | C1: Max [pcs] to be stored | D1: Max amount of boxes | E1: Amout of picked boxes / year | F1: Number of pickups / year | G1: Avarage of picked boxes/ pickup
A2: MT00005 | B2: 90x37x10 | C2: 120 | D2: =C2/10 -> 12 | E2: {=(INDEX(Stock_history!$B$1:$B$506,_xlfn.XMATCH('Indexable Inserts'!A2,Stock_history!$A$1:$A$506)))*-1/10} -> 29 | F2: {=(INDEX(Stock_history!$C$1:$C$506,_xlfn.XMATCH('Indexable Inserts'!A2,Stock_history!$A$1:$A$506)))} -> 17 | G2: {=(INDEX(Stock_history!$D$1:$D$506,_xlfn.XMATCH('Indexable Inserts'!A2,Stock_history!$A$1:$A$506)))*-1/10} -> 1.71
A3: MT00185 | B3: 90x37x10 | C3: 110 | D3: =C3/10 -> 11 | E3: {=(INDEX(Stock_history!$B$1:$B$506,_xlfn.XMATCH('Indexable Inserts'!A3,Stock_history!$A$1:$A$506)))*-1/10} -> 33.9 | F3: {=(INDEX(Stock_history!$C$1:$C$506,_xlfn.XMATCH('Indexable Inserts'!A3,Stock_history!$A$1:$A$506)))} -> 34 | G3: {=(INDEX(Stock_history!$D$1:$D$506,_xlfn.XMATCH('Indexable Inserts'!A3,Stock_history!$A$1:$A$506)))*-1/10} -> 1
A4: MT00348 | B4: 110x50x13 | C4: 120 | D4: =C4/10 -> 12 | E4: {=(INDEX(Stock_history!$B$1:$B$506,_xlfn.XMATCH('Indexable Inserts'!A4,Stock_history!$A$1:$A$506)))*-1/10} -> 163 | F4: {=(INDEX(Stock_history!$C$1:$C$506,_xlfn.XMATCH('Indexable Inserts'!A4,Stock_history!$A$1:$A$506)))} -> 85 | G4: {=(INDEX(Stock_history!$D$1:$D$506,_xlfn.XMATCH('Indexable Inserts'!A4,Stock_history!$A$1:$A$506)))*-1/10} -> 1.92
A5: MT00404 | B5: 110x50x13 | C5: 50 | D5: =C5/10 -> 5 | E5: {=(INDEX(Stock_history!$B$1:$B$506,_xlfn.XMATCH('Indexable Inserts'!A5,Stock_history!$A$1:$A$506)))*-1/10} -> 5 | F5: {=(INDEX(Stock_history!$C$1:$C$506,_xlfn.XMATCH('Indexable Inserts'!A5,Stock_history!$A$1:$A$506)))} -> 4 | G5: {=(INDEX(Stock_history!$D$1:$D$506,_xlfn.XMATCH('Indexable Inserts'!A5,Stock_history!$A$1:$A$506)))*-1/10} -> 1.25
A6: MT00987 | B6: 110x50x13 | C6: 30 | D6: =C6/10 -> 3 | E6: {=(INDEX(Stock_history!$B$1:$B$506,_xlfn.XMATCH('Indexable Inserts'!A6,Stock_history!$A$1:$A$506)))*-1/10} -> 0.5 | F6: {=(INDEX(Stock_history!$C$1:$C$506,_xlfn.XMATCH('Indexable Inserts'!A6,Stock_history!$A$1:$A$506)))} -> 1 | G6: {=(INDEX(Stock_history!$D$1:$D$506,_xlfn.XMATCH('Indexable Inserts'!A6,Stock_history!$A$1:$A$506)))*-1/10} -> 0.5
A7: MT00988 | B7: 110x50x13 | C7: 30 | D7: =C7/10 -> 3 | E7: {=(INDEX(Stock_history!$B$1:$B$506,_xlfn.XMATCH('Indexable Inserts'!A7,Stock_history!$A$1:$A$506)))*-1/10} -> 7.5 | F7: {=(INDEX(Stock_history!$C$1:$C$506,_xlfn.XMATCH('Indexable Inserts'!A7,Stock_history!$A$1:$A$506)))} -> 7 | G7: {=(INDEX(Stock_history!$D$1:$D$506,_xlfn.XMATCH('Indexable Inserts'!A7,Stock_history!$A$1:$A$506)))*-1/10} -> 1.07
A8: MT01036 | B8: 90x37x10 | C8: 30 | D8: =C8/10 -> 3 | E8: {=(INDEX(Stock_history!$B$1:$B$506,_xlfn.XMATCH('Indexable Inserts'!A8,Stock_history!$A$1:$A$506)))*-1/10} -> 1 | F8: {=(INDEX(Stock_history!$C$1:$C$506,_xlfn.XMATCH('Indexable Inserts'!A8,Stock_history!$A$1:$A$506)))} -> 1 | G8: {=(INDEX(Stock_history!$D$1:$D$506,_xlfn.XMATCH('Indexable Inserts'!A8,Stock_history!$A$1:$A$506)))*-1/10} -> 1
A9: MT01037 | B9: 90x37x10 | C9: 40 | D9: =C9/10 -> 4 | E9: {=(INDEX(Stock_history!$B$1:$B$506,_xlfn.XMATCH('Indexable Inserts'!A9,Stock_history!$A$1:$A$506)))*-1/10} -> 11.4 | F9: {=(INDEX(Stock_history!$C$1:$C$506,_xlfn.XMATCH('Indexable Inserts'!A9,Stock_history!$A$1:$A$506)))} -> 8 | G9: {=(INDEX(Stock_history!$D$1:$D$506,_xlfn.XMATCH('Indexable Inserts'!A9,Stock_history!$A$1:$A$506)))*-1/10} -> 1.43
A10: MT01060 | B10: 90x37x10 | C10: 40 | D10: =C10/10 -> 4 | E10: {=(INDEX(Stock_history!$B$1:$B$506,_xlfn.XMATCH('Indexable Inserts'!A10,Stock_history!$A$1:$A$506)))*-1/10} -> 5 | F10: {=(INDEX(Stock_history!$C$1:$C$506,_xlfn.XMATCH('Indexable Inserts'!A10,Stock_history!$A$1:$A$506)))} -> 5 | G10: {=(INDEX(Stock_history!$D$1:$D$506,_xlfn.XMATCH('Indexable Inserts'!A10,Stock_history!$A$1:$A$506)))*-1/10} -> 1
A11: MT01061 | B11: 90x37x10 | C11: 30 | D11: =C11/10 -> 3 | E11: {=(INDEX(Stock_history!$B$1:$B$506,_xlfn.XMATCH('Indexable Inserts'!A11,Stock_history!$A$1:$A$506)))*-1/10} -> #N/A | F11: {=(INDEX(Stock_history!$C$1:$C$506,_xlfn.XMATCH('Indexable Inserts'!A11,Stock_history!$A$1:$A$506)))} -> #N/A | G11: {=(INDEX(Stock_history!$D$1:$D$506,_xlfn.XMATCH('Indexable Inserts'!A11,Stock_history!$A$1:$A$506)))*-1/10} -> #N/A
A12: MT01062 | B12: 110x50x13 | C12: 30 | D12: =C12/10 -> 3 | E12: {=(INDEX(Stock_history!$B$1:$B$506,_xlfn.XMATCH('Indexable Inserts'!A12,Stock_history!$A$1:$A$506)))*-1/10} -> 2 | F12: {=(INDEX(Stock_history!$C$1:$C$506,_xlfn.XMATCH('Indexable Inserts'!A12,Stock_history!$A$1:$A$506)))} -> 2 | G12: {=(INDEX(Stock_history!$D$1:$D$506,_xlfn.XMATCH('Indexable Inserts'!A12,Stock_history!$A$1:$A$506)))*-1/10} -> 1
A13: MT01063 | B13: 90x37x10 | C13: 40 | D13: =C13/10 -> 4 | E13: {=(INDEX(Stock_history!$B$1:$B$506,_xlfn.XMATCH('Indexable Inserts'!A13,Stock_history!$A$1:$A$506)))*-1/10} -> 3 | F13: {=(INDEX(Stock_history!$C$1:$C$506,_xlfn.XMATCH('Indexable Inserts'!A13,Stock_history!$A$1:$A$506)))} -> 3 | G13: {=(INDEX(Stock_history!$D$1:$D$506,_xlfn.XMATCH('Indexable Inserts'!A13,Stock_history!$A$1:$A$506)))*-1/10} -> 1
... A75: MT00055 | B75: 130x55x13 | C75: 70 | D75: =C75/10 -> 7 | E75: {=(INDEX(Stock_history!$B$1:$B$506,_xlfn.XMATCH('Indexable Inserts'!A75,Stock_history!$A$1:$A$506)))*-1/10} -> 14 | F75: {=(INDEX(Stock_history!$C$1:$C$506,_xlfn.XMATCH('Indexable Inserts'!A75,Stock_history!$A$1:$A$506)))} -> 11 | G75: {=(INDEX(Stock_history!$D$1:$D$506,_xlfn.XMATCH('Indexable Inserts'!A75,Stock_history!$A$1:$A$506)))*-1/10} -> 1.27
A76: MT00066 | B76: 95x25x14 | C76: 40 | D76: =C76/5 -> 8 | E76: {=(INDEX(Stock_history!$B$1:$B$506,_xlfn.XMATCH('Indexable Inserts'!A76,Stock_history!$A$1:$A$506)))*-1/5} -> 3 | F76: {=(INDEX(Stock_history!$C$1:$C$506,_xlfn.XMATCH('Indexable Inserts'!A76,Stock_history!$A$1:$A$506)))} -> 2 | G76: {=(INDEX(Stock_history!$D$1:$D$506,_xlfn.XMATCH('Indexable Inserts'!A76,Stock_history!$A$1:$A$506)))*-1/5} -> 1.5
A77: MT00074 | B77: 130x55x13 | C77: 40 | D77: =C77/10 -> 4 | E77: {=(INDEX(Stock_history!$B$1:$B$506,_xlfn.XMATCH('Indexable Inserts'!A77,Stock_history!$A$1:$A$506)))*-1/10} -> 5 | F77: {=(INDEX(Stock_history!$C$1:$C$506,_xlfn.XMATCH('Indexable Inserts'!A77,Stock_history!$A$1:$A$506)))} -> 5 | G77: {=(INDEX(Stock_history!$D$1:$D$506,_xlfn.XMATCH('Indexable Inserts'!A77,Stock_history!$A$1:$A$506)))*-1/10} -> 1
A78: MT00084 | B78: 130x55x13 | C78: 30 | D78: =C78/10 -> 3 | E78: {=(INDEX(Stock_history!$B$1:$B$506,_xlfn.XMATCH('Indexable Inserts'!A78,Stock_history!$A$1:$A$506)))*-1/10} -> 3.1 | F78: {=(INDEX(Stock_history!$C$1:$C$506,_xlfn.XMATCH('Indexable Inserts'!A78,Stock_history!$A$1:$A$506)))} -> 4 | G78: {=(INDEX(Stock_history!$D$1:$D$506,_xlfn.XMATCH('Indexable Inserts'!A78,Stock_history!$A$1:$A$506)))*-1/10} -> 0.78
A79: MT00126 | B79: 98x40x15 | C79: 70 | D79: =C79/10 -> 7 | E79: {=(INDEX(Stock_history!$B$1:$B$506,_xlfn.XMATCH('Indexable Inserts'!A79,Stock_history!$A$1:$A$506)))*-1/10} -> 14 | F79: {=(INDEX(Stock_history!$C$1:$C$506,_xlfn.XMATCH('Indexable Inserts'!A79,Stock_history!$A$1:$A$506)))} -> 11 | G79: {=(INDEX(Stock_history!$D$1:$D$506,_xlfn.XMATCH('Indexable Inserts'!A79,Stock_history!$A$1:$A$506)))*-1/10} -> 1.27
A80: MT00135 | B80: 95x25x14 | C80: 60 | D80: =C80/5 -> 12 | E80: {=(INDEX(Stock_history!$B$1:$B$506,_xlfn.XMATCH('Indexable Inserts'!A80,Stock_history!$A$1:$A$506)))*-1/5} -> 8 | F80: {=(INDEX(Stock_history!$C$1:$C$506,_xlfn.XMATCH('Indexable Inserts'!A80,Stock_history!$A$1:$A$506)))} -> 5 | G80: {=(INDEX(Stock_history!$D$1:$D$506,_xlfn.XMATCH('Indexable Inserts'!A80,Stock_history!$A$1:$A$506)))*-1/5} -> 1.6
A81: MT00157 | B81: 98x40x15 | C81: 110 | D81: =C81/10 -> 11 | E81: {=(INDEX(Stock_history!$B$1:$B$506,_xlfn.XMATCH('Indexable Inserts'!A81,Stock_history!$A$1:$A$506)))*-1/10} -> 44 | F81: {=(INDEX(Stock_history!$C$1:$C$506,_xlfn.XMATCH('Indexable Inserts'!A81,Stock_history!$A$1:$A$506)))} -> 39 | G81: {=(INDEX(Stock_history!$D$1:$D$506,_xlfn.XMATCH('Indexable Inserts'!A81,Stock_history!$A$1:$A$506)))*-1/10} -> 1.13
A82: MT00163 | B82: 98x40x15 | C82: 60 | D82: =C82/10 -> 6 | E82: {=(INDEX(Stock_history!$B$1:$B$506,_xlfn.XMATCH('Indexable Inserts'!A82,Stock_history!$A$1:$A$506)))*-1/10} -> 7 | F82: {=(INDEX(Stock_history!$C$1:$C$506,_xlfn.XMATCH('Indexable Inserts'!A82,Stock_history!$A$1:$A$506)))} -> 6 | G82: {=(INDEX(Stock_history!$D$1:$D$506,_xlfn.XMATCH('Indexable Inserts'!A82,Stock_history!$A$1:$A$506)))*-1/10} -> 1.17
A83: MT00177 | B83: 98x40x15 | C83: 70 | D83: =C83/10 -> 7 | E83: {=(INDEX(Stock_history!$B$1:$B$506,_xlfn.XMATCH('Indexable Inserts'!A83,Stock_history!$A$1:$A$506)))*-1/10} -> 11 | F83: {=(INDEX(Stock_history!$C$1:$C$506,_xlfn.XMATCH('Indexable Inserts'!A83,Stock_history!$A$1:$A$506)))} -> 9 | G83: {=(INDEX(Stock_history!$D$1:$D$506,_xlfn.XMATCH('Indexable Inserts'!A83,Stock_history!$A$1:$A$506)))*-1/10} -> 1.22
A84: MT00193 | B84: 95x25x14 | C84: 40 | D84: =C84/5 -> 8 | E84: {=(INDEX(Stock_history!$B$1:$B$506,_xlfn.XMATCH('Indexable Inserts'!A84,Stock_history!$A$1:$A$506)))*-1/5} -> 12 | F84: {=(INDEX(Stock_history!$C$1:$C$506,_xlfn.XMATCH('Indexable Inserts'!A84,Stock_history!$A$1:$A$506)))} -> 8 | G84: {=(INDEX(Stock_history!$D$1:$D$506,_xlfn.XMATCH('Indexable Inserts'!A84,Stock_history!$A$1:$A$506)))*-1/5} -> 1.5
A85: MT00209 | B85: 138x58x14 | C85: 300 | D85: =C85/10 -> 30 | E85: {=(INDEX(Stock_history!$B$1:$B$506,_xlfn.XMATCH('Indexable Inserts'!A85,Stock_history!$A$1:$A$506)))*-1/10} -> 55 | F85: {=(INDEX(Stock_history!$C$1:$C$506,_xlfn.XMATCH('Indexable Inserts'!A85,Stock_history!$A$1:$A$506)))} -> 34 | G85: {=(INDEX(Stock_history!$D$1:$D$506,_xlfn.XMATCH('Indexable Inserts'!A85,Stock_history!$A$1:$A$506)))*-1/10} -> 1.62
A86: MT00214 | B86: 95x25x14 | C86: 40 | D86: =C86/5 -> 8 | E86: {=(INDEX(Stock_history!$B$1:$B$506,_xlfn.XMATCH('Indexable Inserts'!A86,Stock_history!$A$1:$A$506)))*-1/5} -> 8 | F86: {=(INDEX(Stock_history!$C$1:$C$506,_xlfn.XMATCH('Indexable Inserts'!A86,Stock_history!$A$1:$A$506)))} -> 6 | G86: {=(INDEX(Stock_history!$D$1:$D$506,_xlfn.XMATCH('Indexable Inserts'!A86,Stock_history!$A$1:$A$506)))*-1/5} -> 1.34
A87: MT00215 | B87: 95x25x14 | C87: 40 | D87: =C87/5 -> 8 | E87: {=(INDEX(Stock_history!$B$1:$B$506,_xlfn.XMATCH('Indexable Inserts'!A87,Stock_history!$A$1:$A$506)))*-1/5} -> 7 | F87: {=(INDEX(Stock_history!$C$1:$C$506,_xlfn.XMATCH('Indexable Inserts'!A87,Stock_history!$A$1:$A$506)))} -> 5 | G87: {=(INDEX(Stock_history!$D$1:$D$506,_xlfn.XMATCH('Indexable Inserts'!A87,Stock_history!$A$1:$A$506)))*-1/5} -> 1.4
A88: MT00225 | B88: 98x40x15 | C88: 110 | D88: =C88/10 -> 11 | E88: {=(INDEX(Stock_history!$B$1:$B$506,_xlfn.XMATCH('Indexable Inserts'!A88,Stock_history!$A$1:$A$506)))*-1/10} -> 50 | F88: {=(INDEX(Stock_history!$C$1:$C$506,_xlfn.XMATCH('Indexable Inserts'!A88,Stock_history!$A$1:$A$506)))} -> 41 | G88: {=(INDEX(Stock_history!$D$1:$D$506,_xlfn.XMATCH('Indexable Inserts'!A88,Stock_history!$A$1:$A$506)))*-1/10} -> 1.22
A89: MT00226 | B89: 91x46x13 | C89: 50 | D89: =C89/10 -> 5 | E89: {=(INDEX(Stock_history!$B$1:$B$506,_xlfn.XMATCH('Indexable Inserts'!A89,Stock_history!$A$1:$A$506)))*-1/10} -> 6 | F89: {=(INDEX(Stock_history!$C$1:$C$506,_xlfn.XMATCH('Indexable Inserts'!A89,Stock_history!$A$1:$A$506)))} -> 5 | G89: {=(INDEX(Stock_history!$D$1:$D$506,_xlfn.XMATCH('Indexable Inserts'!A89,Stock_history!$A$1:$A$506)))*-1/10} -> 1.2
A90: MT00227 | B90: 91x46x13 | C90: 60 | D90: =C90/10 -> 6 | E90: {=(INDEX(Stock_history!$B$1:$B$506,_xlfn.XMATCH('Indexable Inserts'!A90,Stock_history!$A$1:$A$506)))*-1/10} -> 7 | F90: {=(INDEX(Stock_history!$C$1:$C$506,_xlfn.XMATCH('Indexable Inserts'!A90,Stock_history!$A$1:$A$506)))} -> 5 | G90: {=(INDEX(Stock_history!$D$1:$D$506,_xlfn.XMATCH('Indexable Inserts'!A90,Stock_history!$A$1:$A$506)))*-1/10} -> 1.4
A91: MT00301 | B91: 91x46x13 | C91: 60 | D91: =C91/10 -> 6 | E91: {=(INDEX(Stock_history!$B$1:$B$506,_xlfn.XMATCH('Indexable Inserts'!A91,Stock_history!$A$1:$A$506)))*-1/10} -> 12 | F91: {=(INDEX(Stock_history!$C$1:$C$506,_xlfn.XMATCH('Indexable Inserts'!A91,Stock_history!$A$1:$A$506)))} -> 10 | G91: {=(INDEX(Stock_history!$D$1:$D$506,_xlfn.XMATCH('Indexable Inserts'!A91,Stock_history!$A$1:$A$506)))*-1/10} -> 1.2
A92: MT00302 | B92: 91x38x11 | C92: 20 | D92: =C92/10 -> 2 | E92: {=(INDEX(Stock_history!$B$1:$B$506,_xlfn.XMATCH('Indexable Inserts'!A92,Stock_history!$A$1:$A$506)))*-1/10} -> 2 | F92: {=(INDEX(Stock_history!$C$1:$C$506,_xlfn.XMATCH('Indexable Inserts'!A92,Stock_history!$A$1:$A$506)))} -> 3 | G92: {=(INDEX(Stock_history!$D$1:$D$506,_xlfn.XMATCH('Indexable Inserts'!A92,Stock_history!$A$1:$A$506)))*-1/10} -> 0.67
A93: MT00359 | B93: 91x46x13 | C93: 40 | D93: =C93/10 -> 4 | E93: {=(INDEX(Stock_history!$B$1:$B$506,_xlfn.XMATCH('Indexable Inserts'!A93,Stock_history!$A$1:$A$506)))*-1/10} -> 5 | F93: {=(INDEX(Stock_history!$C$1:$C$506,_xlfn.XMATCH('Indexable Inserts'!A93,Stock_history!$A$1:$A$506)))} -> 5 | G93: {=(INDEX(Stock_history!$D$1:$D$506,_xlfn.XMATCH('Indexable Inserts'!A93,Stock_history!$A$1:$A$506)))*-1/10} -> 1
A94: MT00367 | B94: 113x76x17 | C94: 50 | D94: =C94/5 -> 10 | E94: {=(INDEX(Stock_history!$B$1:$B$506,_xlfn.XMATCH('Indexable Inserts'!A94,Stock_history!$A$1:$A$506)))*-1/5} -> 12 | F94: {=(INDEX(Stock_history!$C$1:$C$506,_xlfn.XMATCH('Indexable Inserts'!A94,Stock_history!$A$1:$A$506)))} -> 8 | G94: {=(INDEX(Stock_history!$D$1:$D$506,_xlfn.XMATCH('Indexable Inserts'!A94,Stock_history!$A$1:$A$506)))*-1/5} -> 1.5
A95: MT00384 | B95: 56x53x23 | C95: 8 | D95: =C95/2 -> 4 | E95: {=(INDEX(Stock_history!$B$1:$B$506,_xlfn.XMATCH('Indexable Inserts'!A95,Stock_history!$A$1:$A$506)))*-1/2} -> #N/A | F95: {=(INDEX(Stock_history!$C$1:$C$506,_xlfn.XMATCH('Indexable Inserts'!A95,Stock_history!$A$1:$A$506)))} -> #N/A | G95: {=(INDEX(Stock_history!$D$1:$D$506,_xlfn.XMATCH('Indexable Inserts'!A95,Stock_history!$A$1:$A$506)))*-1/2} -> #N/A
A96: MT00387 | B96: 139x56x20 | C96: 80 | D96: =C96/10 -> 8 | E96: {=(INDEX(Stock_history!$B$1:$B$506,_xlfn.XMATCH('Indexable Inserts'!A96,Stock_history!$A$1:$A$506)))*-1/10} -> 23 | F96: {=(INDEX(Stock_history!$C$1:$C$506,_xlfn.XMATCH('Indexable Inserts'!A96,Stock_history!$A$1:$A$506)))} -> 18 | G96: {=(INDEX(Stock_history!$D$1:$D$506,_xlfn.XMATCH('Indexable Inserts'!A96,Stock_history!$A$1:$A$506)))*-1/10} -> 1.28
A97: MT00440 | B97: 91x46x13 | C97: 20 | D97: =C97/10 -> 2 | E97: {=(INDEX(Stock_history!$B$1:$B$506,_xlfn.XMATCH('Indexable Inserts'!A97,Stock_history!$A$1:$A$506)))*-1/10} -> 1 | F97: {=(INDEX(Stock_history!$C$1:$C$506,_xlfn.XMATCH('Indexable Inserts'!A97,Stock_history!$A$1:$A$506)))} -> 1 | G97: {=(INDEX(Stock_history!$D$1:$D$506,_xlfn.XMATCH('Indexable Inserts'!A97,Stock_history!$A$1:$A$506)))*-1/10} -> 1
A98: MT00444 | B98: 65x38x13 | C98: 36 | D98: =C98/1 -> 36 | E98: {=(INDEX(Stock_history!$B$1:$B$506,_xlfn.XMATCH('Indexable Inserts'!A98,Stock_history!$A$1:$A$506)))*-1} -> 46 | F98: {=(INDEX(Stock_history!$C$1:$C$506,_xlfn.XMATCH('Indexable Inserts'!A98,Stock_history!$A$1:$A$506)))} -> 15 | G98: {=(INDEX(Stock_history!$D$1:$D$506,_xlfn.XMATCH('Indexable Inserts'!A98,Stock_history!$A$1:$A$506)))*-1} -> 3.1
A99: MT00448 | B99: 95x25x14 | C99: 30 | D99: =C99/10 -> 3 | E99: {=(INDEX(Stock_history!$B$1:$B$506,_xlfn.XMATCH('Indexable Inserts'!A99,Stock_history!$A$1:$A$506)))*-1/10} -> 3 | F99: {=(INDEX(Stock_history!$C$1:$C$506,_xlfn.XMATCH('Indexable Inserts'!A99,Stock_history!$A$1:$A$506)))} -> 4 | G99: {=(INDEX(Stock_history!$D$1:$D$506,_xlfn.XMATCH('Indexable Inserts'!A99,Stock_history!$A$1:$A$506)))*-1/10} -> 0.75
A100: MT00456 | B100: 91x46x13 | C100: 20 | D100: =C100/10 -> 2 | E100: {=(INDEX(Stock_history!$B$1:$B$506,_xlfn.XMATCH('Indexable Inserts'!A100,Stock_history!$A$1:$A$506)))*-1/10} -> 2 | F100: {=(INDEX(Stock_history!$C$1:$C$506,_xlfn.XMATCH('Indexable Inserts'!A100,Stock_history!$A$1:$A$506)))} -> 2 | G100: {=(INDEX(Stock_history!$D$1:$D$506,_xlfn.XMATCH('Indexable Inserts'!A100,Stock_history!$A$1:$A$506)))*-1/10} -> 1
A101: MT00457 | B101: 91x46x13 | C101: 20 | D101: =C101/10 -> 2 | E101: {=(INDEX(Stock_history!$B$1:$B$506,_xlfn.XMATCH('Indexable Inserts'!A101,Stock_history!$A$1:$A$506)))*-1/10} -> 0.5 | F101: {=(INDEX(Stock_history!$C$1:$C$506,_xlfn.XMATCH('Indexable Inserts'!A101,Stock_history!$A$1:$A$506)))} -> 1 | G101: {=(INDEX(Stock_history!$D$1:$D$506,_xlfn.XMATCH('Indexable Inserts'!A101,Stock_history!$A$1:$A$506)))*-1/10} -> 0.5
...

Sheet Stock_history
A1: MT01200 | B1: -7098 | C1: 297 | D1: -23.9
A2: MT00348 | B2: -1630 | C2: 85 | D2: -19.2
A3: MT00579 | B3: -62 | C3: 61 | D3: -1
A4: MT01214 | B4: -51 | C4: 50 | D4: -1
A5: MT00549 | B5: -59 | C5: 48 | D5: -1.2
A6: MT00098 | B6: -550 | C6: 47 | D6: -11.7
A7: MT00570 | B7: -52 | C7: 42 | D7: -1.2
A8: MT00225 | B8: -500 | C8: 41 | D8: -12.2
A9: MT01017 | B9: -61 | C9: 41 | D9: -1.5
A10: MT00586 | B10: -68 | C10: 39 | D10: -1.7
A11: MT00052 | B11: -500 | C11: 39 | D11: -12.8
A12: MT00157 | B12: -440 | C12: 39 | D12: -11.3
... A506: MT00786 | B506: -1 | C506: 1 | D506: -1
